Workbook

Sheet Scoring
C3: Action | D3: Points | E3: Table | F3: Calculation | G3: Notes
C4: For playing up to 60 minutes | D4: 1 | E4: stg_playerstats | G4: Mutually exclusive?
C5: For playing 60 minutes or more (excluding stoppage time) | D5: 2 | E5: stg_playerstats | G5: Mutually exclusive?
C6: For each goal scored by a goalkeeper | D6: 10
C7: For each goal scored by a defender | D7: 6
C8: For each goal scored by a midfielder | D8: 5
C9: For each goal scored by a forward | D9: 4
C10: For each goal assist | D10: 3
C11: For a clean sheet by a goalkeeper or defender | D11: 4
C12: For a clean sheet by a midfielder | D12: 1
C13: For every 3 shot saves by a goalkeeper | D13: 1
C14: For accumulating 10 or more Clearances, Blocks, Interceptions (CBI) & Tackles (defenders) | D14: 2
C15: For accumulating 12 or more Clearances, Blocks, Interceptions (CBI), Tackles & Recoveries (midfielders & forwards) | D15: 2
C16: For each penalty save | D16: 5
C17: For each penalty miss | D17: -2
... C22: For each own goal | D22: -2
C24: Defensive Contribution
C25: The addition of Defensive Contribution points in Fantasy helps reward outfield players who may not earn a goal or an assist but still make significant contributions during a match.
C26: Any defender who reaches an accumulative total of 10 or more clearances, blocks, interceptions (CBI) and tackles in a single match will earn 2 points.
C27: Any midfielder or forward who reaches an accumulative total of 12 or more clearances, blocks, interceptions (CBI), tackles and recoveries will earn 2 points.
C28: See the ‘NEW’ section for more information.
C30: A clean sheet is awarded for not conceding a goal whilst on the pitch and playing at least 60 minutes (excluding stoppage time).
C31: If a player has been substituted when a goal is conceded this will not affect any clean sheet bonus.
C33: f a player receives a red card, they will continue to be penalised for goals conceded by their team.
C34: Red card deductions include any points deducted for yellow cards.
C36: Assists
C37: Fantasy assists are awarded to the player from the goal scoring team who last touches the ball before their teammate who scores the goal.The final touch can be a pass, an inadvertent touch, or a shot.
C38: Passes
... C77: Players score BPS points based on the following statistics (one point for each unless otherwise stated):
C78: Action | D78: BPS
C79: Playing 1 to 60 minutes | D79: 3
C80: Playing over 60 minutes | D80: 6
C81: Scoring a goal direct from a penalty | D81: 12
C82: Goalkeepers and defenders scoring a goal | D82: 12
C83: Midfielders scoring a goal | D83: 18
C84: Forwards scoring a goal | D84: 24
C85: Assists | D85: 9
C86: Goalkeepers and defenders keeping a clean sheet | D86: 12
C87: Saving a penalty | D87: 8
C88: Successful open play cross | D88: 1
...

Sheet Draft Optimizer
K1: Notes
E2: =SUM(E5:E19)+0.1 -> 99.5 | K2: Mainoo GW 22 performance?
B4: PositionType | C4: PositionSubType | D4: web_name | E4: price | F4: team | G4: position | H4: notes
B5: FOR2 | C5: FOR2 | D5: Haaland | E5: =_xlfn.XLOOKUP(D5,player_cost!B:B,player_cost!F:F) -> 15.1 | F5: =_xlfn.XLOOKUP(D5,player_cost!B:B,player_cost!E:E) -> MCI | G5: =_xlfn.XLOOKUP(D5,player_cost!B:B,player_cost!C:C) -> Forward
B6: MID5 | C6: MID5 | D6: B.Fernandes | E6: =_xlfn.XLOOKUP(D6,player_cost!B:B,player_cost!F:F) -> 9.1 | F6: =_xlfn.XLOOKUP(D6,player_cost!B:B,player_cost!E:E) -> MUN | G6: =_xlfn.XLOOKUP(D6,player_cost!B:B,player_cost!C:C) -> Midfielder
B7: MID3 | C7: MID3 | D7: Wirtz | E7: =_xlfn.XLOOKUP(D7,player_cost!B:B,player_cost!F:F) -> 8.2 | F7: =_xlfn.XLOOKUP(D7,player_cost!B:B,player_cost!E:E) -> LIV | G7: =_xlfn.XLOOKUP(D7,player_cost!B:B,player_cost!C:C) -> Midfielder
B8: MID2 | C8: MID2 | D8: Mbeumo | E8: =_xlfn.XLOOKUP(D8,player_cost!B:B,player_cost!F:F) -> 8.1 | F8: =_xlfn.XLOOKUP(D8,player_cost!B:B,player_cost!E:E) -> MUN | G8: =_xlfn.XLOOKUP(D8,player_cost!B:B,player_cost!C:C) -> Midfielder
B9: FOR1 | C9: FOR1 | D9: Thiago | E9: =_xlfn.XLOOKUP(D9,player_cost!B:B,player_cost!F:F) -> 7.1 | F9: =_xlfn.XLOOKUP(D9,player_cost!B:B,player_cost!E:E) -> BRE | G9: =_xlfn.XLOOKUP(D9,player_cost!B:B,player_cost!C:C) -> Forward
B10: DEF4 | C10: DEF4 | D10: Gabriel | E10: =_xlfn.XLOOKUP(D10,player_cost!B:B,player_cost!F:F) -> 6.7 | F10: =_xlfn.XLOOKUP(D10,player_cost!B:B,player_cost!E:E) -> ARS | G10: =_xlfn.XLOOKUP(D10,player_cost!B:B,player_cost!C:C) -> Defender
B11: MID1 | C11: MID1 | D11: Mitoma | E11: =_xlfn.XLOOKUP(D11,player_cost!B:B,player_cost!F:F) -> 6.1 | F11: =_xlfn.XLOOKUP(D11,player_cost!B:B,player_cost!E:E) -> BHA | G11: =_xlfn.XLOOKUP(D11,player_cost!B:B,player_cost!C:C) -> Midfielder
B12: FOR3 | C12: FOR3 | D12: Calvert-Lewin | E12: =_xlfn.XLOOKUP(D12,player_cost!B:B,player_cost!F:F) -> 6 | F12: =_xlfn.XLOOKUP(D12,player_cost!B:B,player_cost!E:E) -> LEE | G12: =_xlfn.XLOOKUP(D12,player_cost!B:B,player_cost!C:C) -> Forward
B13: GK1 | C13: GK1 | D13: Raya | E13: =_xlfn.XLOOKUP(D13,player_cost!B:B,player_cost!F:F) -> 5.9 | F13: =_xlfn.XLOOKUP(D13,player_cost!B:B,player_cost!E:E) -> ARS | G13: =_xlfn.XLOOKUP(D13,player_cost!B:B,player_cost!C:C) -> Goalkeeper
B14: MID4 | C14: MID4 | D14: Anderson | E14: =_xlfn.XLOOKUP(D14,player_cost!B:B,player_cost!F:F) -> 5.3 | F14: =_xlfn.XLOOKUP(D14,player_cost!B:B,player_cost!E:E) -> NFO | G14: =_xlfn.XLOOKUP(D14,player_cost!B:B,player_cost!C:C) -> Midfielder
B15: DEF1 | C15: DEF1 | D15: Ballard | E15: =_xlfn.XLOOKUP(D15,player_cost!B:B,player_cost!F:F) -> 4.6 | F15: =_xlfn.XLOOKUP(D15,player_cost!B:B,player_cost!E:E) -> SUN | G15: =_xlfn.XLOOKUP(D15,player_cost!B:B,player_cost!C:C) -> Defender
B16: DEF5 | C16: DEF5 | D16: Andersen | E16: =_xlfn.XLOOKUP(D16,player_cost!B:B,player_cost!F:F) -> 4.6 | F16: =_xlfn.XLOOKUP(D16,player_cost!B:B,player_cost!E:E) -> FUL | G16: =_xlfn.XLOOKUP(D16,player_cost!B:B,player_cost!C:C) -> Defender
... B19: GK2 | C19: GK2 | D19: Dúbravka | E19: =_xlfn.XLOOKUP(D19,player_cost!B:B,player_cost!F:F) -> 4 | F19: =_xlfn.XLOOKUP(D19,player_cost!B:B,player_cost!E:E) -> BUR | G19: =_xlfn.XLOOKUP(D19,player_cost!B:B,player_cost!C:C) -> Goalkeeper
B22: Watchlist | C22: Other Factors
B23: Ballard | C23: Team fixture difficulty (better calcultion)
B24: Mainoo | C24: Do a midfielder xg model
B25: Andersen
B26: Mitoma
B27: Gakpo
B28: Barnes
B29: Aaronson
B30: Schade
B31: Anderson
B32: Wirtz
B33: Garner
B34: Amad

Sheet player_cost
A1: player_id | B1: web_name | C1: position | D1: team_code | E1: team_name | F1: now_cost
A2: 430 | B2: Haaland | C2: Forward | D2: 43 | E2: MCI | F2: 15.1
A3: 381 | B3: M.Salah | C3: Midfielder | D3: 14 | E3: LIV | F3: 14
A4: 235 | B4: Palmer | C4: Midfielder | D4: 8 | E4: CHE | F4: 10.4
A5: 499 | B5: Isak | C5: Forward | D5: 14 | E5: LIV | F5: 10.3
A6: 16 | B6: Saka | C6: Midfielder | D6: 3 | E6: ARS | F6: 10.2
A7: 449 | B7: B.Fernandes | C7: Midfielder | D7: 1 | E7: MUN | F7: 9.1
A8: 661 | B8: Ekitiké | C8: Forward | D8: 14 | E8: LIV | F8: 8.9
A9: 64 | B9: Watkins | C9: Forward | D9: 7 | E9: AVL | F9: 8.8
A10: 666 | B10: Gyökeres | C10: Forward | D10: 3 | E10: ARS | F10: 8.7
A11: 414 | B11: Foden | C11: Midfielder | D11: 43 | E11: MCI | F11: 8.7
A12: 579 | B12: Son | C12: Midfielder | D12: 6 | E12: TOT | F12: 8.5
A13: 413 | B13: Marmoush | C13: Midfielder | D13: 43 | E13: MCI | F13: 8.3
... A797: 378 | B797: Nallo | C797: Defender | D797: 14 | E797: LIV | F797: 3.7
